Workbook

Sheet Instructions
A1: Findings review trail
A2: Purpose | B2: One row per finding. Each role completes its own column group in order; the Stage, Waiting on and Disposition columns update on their own. A finding counts as decided only when its Stage is Closed.
A3: Order | B3: 1. Identity Engineer drafts the finding with evidence (blue). 2. Identity Architect assesses and proposes the solution (green). 3. Zero Trust Architect confirms alignment and maturity (purple). 4. Client decision authority decides (orange).
A4: Which cells to edit | B4: Only the shaded cells in your own column group on the Review Trail sheet. Columns with a dropdown accept list values only. Hover over a column header for what goes in it. Do not edit the grey Disposition formulas, except Tracking ID.
A5: Stage logic | B5: Draft = Engineer section only. Architect reviewed = Architect severity set. With client = Alignment set. Closed = Client decision set.
A6: After the decision | B6: Accept and remediate -> Jira story on the remediation backlog. Accept risk -> exception register (owner, expiry, compensating control). Defer -> status register (owner, risk, disposition, follow-on, target date). Reject -> record the rationale. Put the resulting ID in Tracking ID.
A7: Evidence | B7: Each finding links to its evidence note (findings\F-xx.md) in the approved evidence location: run folder, file SHA-256, run account, data-as-of time and the closure test. Never paste names or account details into this workbook.
A8: Gaps sheet | B8: Everything that is a gap but not a counted finding: Control (a theme that groups findings), Capability (a process or tool that is missing, often raised in a meeting), Evidence (could not be assessed yet: access, inputs), Coverage (nothing measures it) and Decision (waiting on a decision). Link gaps to findings by ID; do not copy findings onto it. Close an Evidence gap when the run lands; it may then produce findings.
A9: Definitions | B9: Severity scale, Zero Trust maturity levels, pillars, decisions and gap types: see the Definitions sheet.
A10: Example row (illustrative) | B10: ID F-EX | Finding: security groups with no accountable owner | Source: 05 ad-groups.csv, OwnerStatus not OK | Count 42 of 310 | Observed severity Low | Architect severity Low; root cause: no owner field in the group request form; solution: make owner mandatory in the request form and assign owners for existing groups; effort M; gate G3 | ZT pillar Governance, Use least privilege, Initial -> Advanced, Aligned | Client decision Accept and remediate -> Remediation backlog (Jira story).
A12: Colour key
A13: Engineer finding | B13: Completed by: Identity Engineer
A14: Architect assessment and solution | B14: Completed by: Identity Architect
A15: Zero Trust alignment | B15: Completed by: Zero Trust Architect
A16: Client response | B16: Completed by: Client decision authority
A17: Disposition | B17: Completed by: Calculated / tracking

Sheet Summary
A1: Findings review trail
A2: Counts update as the Review Trail is filled in. As of: template
A4: Stage | B4: Findings
A5: Draft | B5: =COUNTIF('Review Trail'!$AF$3:$AF$63,A5)
A6: Architect reviewed | B6: =COUNTIF('Review Trail'!$AF$3:$AF$63,A6)
A7: With client | B7: =COUNTIF('Review Trail'!$AF$3:$AF$63,A7)
A8: Closed | B8: =COUNTIF('Review Trail'!$AF$3:$AF$63,A8)
A9: Total | B9: =SUM(B5:B8)
A11: Observed severity | B11: Findings
A12: Critical | B12: =COUNTIF('Review Trail'!$F$3:$F$63,A12)
A13: High | B13: =COUNTIF('Review Trail'!$F$3:$F$63,A13)
A14: Medium | B14: =COUNTIF('Review Trail'!$F$3:$F$63,A14)
A15: Low | B15: =COUNTIF('Review Trail'!$F$3:$F$63,A15)
A16: Total | B16: =SUM(B12:B15)
A18: Architect severity | B18: Findings
A19: Critical | B19: =COUNTIF('Review Trail'!$L$3:$L$63,A19)
A20: High | B20: =COUNTIF('Review Trail'!$L$3:$L$63,A20)
A21: Medium | B21: =COUNTIF('Review Trail'!$L$3:$L$63,A21)
A22: Low | B22: =COUNTIF('Review Trail'!$L$3:$L$63,A22)
A23: Total | B23: =SUM(B19:B22)
A25: Client decision | B25: Findings
A26: Accept and remediate | B26: =COUNTIF('Review Trail'!$AB$3:$AB$63,A26)
A27: Accept risk | B27: =COUNTIF('Review Trail'!$AB$3:$AB$63,A27)
A28: Defer | B28: =COUNTIF('Review Trail'!$AB$3:$AB$63,A28)
A29: Reject | B29: =COUNTIF('Review Trail'!$AB$3:$AB$63,A29)
A30: Total | B30: =SUM(B26:B29)
A32: Zero Trust pillar | B32: Findings
A33: Identity | B33: =COUNTIF('Review Trail'!$T$3:$T$63,A33)
A34: Devices | B34: =COUNTIF('Review Trail'!$T$3:$T$63,A34)
A35: Networks | B35: =COUNTIF('Review Trail'!$T$3:$T$63,A35)
A36: Applications and workloads | B36: =COUNTIF('Review Trail'!$T$3:$T$63,A36)
A37: Data | B37: =COUNTIF('Review Trail'!$T$3:$T$63,A37)
A38: Visibility and analytics | B38: =COUNTIF('Review Trail'!$T$3:$T$63,A38)
A39: Automation and orchestration | B39: =COUNTIF('Review Trail'!$T$3:$T$63,A39)
A40: Governance | B40: =COUNTIF('Review Trail'!$T$3:$T$63,A40)
A41: Total | B41: =SUM(B33:B40)
A43: Gap type | B43: Gaps
A44: Control | B44: =COUNTIF(Gaps!$B$3:$B$43,A44)
A45: Capability | B45: =COUNTIF(Gaps!$B$3:$B$43,A45)
A46: Evidence | B46: =COUNTIF(Gaps!$B$3:$B$43,A46)
...

Sheet Review Trail
A1: Engineer finding (Identity Engineer) | L1: Architect assessment and solution (Identity Architect) | T1: Zero Trust alignment (Zero Trust Architect) | AB1: Client response (Client decision authority) | AF1: Disposition (Calculated / tracking)
A2: ID | B2: Finding | C2: Source and filter | D2: Count | E2: Population | F2: Observed severity | G2: HITRUST CSF | H2: Proposed ZT pillar / principle | I2: Initial recommendation | J2: Evidence note | K2: Engineer date | L2: Architect severity | M2: Root cause | N2: Proposed solution | O2: Effort | P2: Dependencies | Q2: Target gate / sprint | R2: Architect | S2: Architect date | T2: ZT pillar | U2: ZT principle | V2: Current maturity | W2: Target maturity | X2: Alignment | Y2: ZT comment | Z2: ZT Architect | AA2: ZT date | AB2: Client decision | AC2: Decided by | AD2: Decision date | AE2: Client comment | AF2: Stage | AG2: Waiting on | AH2: Disposition | AI2: Tracking ID
AF3: =IF(A3="","",IF(AB3<>"","Closed",IF(X3<>"","With client",IF(L3<>"","Architect reviewed","Draft")))) | AG3: =IF(A3="","",IF(AB3<>"","None",IF(X3<>"","Client",IF(L3<>"","Zero Trust Architect","Identity Architect")))) | AH3: =IF(AB3="Accept and remediate","Remediation backlog (Jira story)",IF(AB3="Accept risk","Exception register (owner, expiry, compensating control)",IF(AB3="Defer","Status register (owner, risk, follow-on, target date)",IF(AB3="Reject","Record the rationale; close",""))))
AF4: =IF(A4="","",IF(AB4<>"","Closed",IF(X4<>"","With client",IF(L4<>"","Architect reviewed","Draft")))) | AG4: =IF(A4="","",IF(AB4<>"","None",IF(X4<>"","Client",IF(L4<>"","Zero Trust Architect","Identity Architect")))) | AH4: =IF(AB4="Accept and remediate","Remediation backlog (Jira story)",IF(AB4="Accept risk","Exception register (owner, expiry, compensating control)",IF(AB4="Defer","Status register (owner, risk, follow-on, target date)",IF(AB4="Reject","Record the rationale; close",""))))
AF5: =IF(A5="","",IF(AB5<>"","Closed",IF(X5<>"","With client",IF(L5<>"","Architect reviewed","Draft")))) | AG5: =IF(A5="","",IF(AB5<>"","None",IF(X5<>"","Client",IF(L5<>"","Zero Trust Architect","Identity Architect")))) | AH5: =IF(AB5="Accept and remediate","Remediation backlog (Jira story)",IF(AB5="Accept risk","Exception register (owner, expiry, compensating control)",IF(AB5="Defer","Status register (owner, risk, follow-on, target date)",IF(AB5="Reject","Record the rationale; close",""))))
AF6: =IF(A6="","",IF(AB6<>"","Closed",IF(X6<>"","With client",IF(L6<>"","Architect reviewed","Draft")))) | AG6: =IF(A6="","",IF(AB6<>"","None",IF(X6<>"","Client",IF(L6<>"","Zero Trust Architect","Identity Architect")))) | AH6: =IF(AB6="Accept and remediate","Remediation backlog (Jira story)",IF(AB6="Accept risk","Exception register (owner, expiry, compensating control)",IF(AB6="Defer","Status register (owner, risk, follow-on, target date)",IF(AB6="Reject","Record the rationale; close",""))))
AF7: =IF(A7="","",IF(AB7<>"","Closed",IF(X7<>"","With client",IF(L7<>"","Architect reviewed","Draft")))) | AG7: =IF(A7="","",IF(AB7<>"","None",IF(X7<>"","Client",IF(L7<>"","Zero Trust Architect","Identity Architect")))) | AH7: =IF(AB7="Accept and remediate","Remediation backlog (Jira story)",IF(AB7="Accept risk","Exception register (owner, expiry, compensating control)",IF(AB7="Defer","Status register (owner, risk, follow-on, target date)",IF(AB7="Reject","Record the rationale; close",""))))
AF8: =IF(A8="","",IF(AB8<>"","Closed",IF(X8<>"","With client",IF(L8<>"","Architect reviewed","Draft")))) | AG8: =IF(A8="","",IF(AB8<>"","None",IF(X8<>"","Client",IF(L8<>"","Zero Trust Architect","Identity Architect")))) | AH8: =IF(AB8="Accept and remediate","Remediation backlog (Jira story)",IF(AB8="Accept risk","Exception register (owner, expiry, compensating control)",IF(AB8="Defer","Status register (owner, risk, follow-on, target date)",IF(AB8="Reject","Record the rationale; close",""))))
AF9: =IF(A9="","",IF(AB9<>"","Closed",IF(X9<>"","With client",IF(L9<>"","Architect reviewed","Draft")))) | AG9: =IF(A9="","",IF(AB9<>"","None",IF(X9<>"","Client",IF(L9<>"","Zero Trust Architect","Identity Architect")))) | AH9: =IF(AB9="Accept and remediate","Remediation backlog (Jira story)",IF(AB9="Accept risk","Exception register (owner, expiry, compensating control)",IF(AB9="Defer","Status register (owner, risk, follow-on, target date)",IF(AB9="Reject","Record the rationale; close",""))))
AF10: =IF(A10="","",IF(AB10<>"","Closed",IF(X10<>"","With client",IF(L10<>"","Architect reviewed","Draft")))) | AG10: =IF(A10="","",IF(AB10<>"","None",IF(X10<>"","Client",IF(L10<>"","Zero Trust Architect","Identity Architect")))) | AH10: =IF(AB10="Accept and remediate","Remediation backlog (Jira story)",IF(AB10="Accept risk","Exception register (owner, expiry, compensating control)",IF(AB10="Defer","Status register (owner, risk, follow-on, target date)",IF(AB10="Reject","Record the rationale; close",""))))
AF11: =IF(A11="","",IF(AB11<>"","Closed",IF(X11<>"","With client",IF(L11<>"","Architect reviewed","Draft")))) | AG11: =IF(A11="","",IF(AB11<>"","None",IF(X11<>"","Client",IF(L11<>"","Zero Trust Architect","Identity Architect")))) | AH11: =IF(AB11="Accept and remediate","Remediation backlog (Jira story)",IF(AB11="Accept risk","Exception register (owner, expiry, compensating control)",IF(AB11="Defer","Status register (owner, risk, follow-on, target date)",IF(AB11="Reject","Record the rationale; close",""))))
AF12: =IF(A12="","",IF(AB12<>"","Closed",IF(X12<>"","With client",IF(L12<>"","Architect reviewed","Draft")))) | AG12: =IF(A12="","",IF(AB12<>"","None",IF(X12<>"","Client",IF(L12<>"","Zero Trust Architect","Identity Architect")))) | AH12: =IF(AB12="Accept and remediate","Remediation backlog (Jira story)",IF(AB12="Accept risk","Exception register (owner, expiry, compensating control)",IF(AB12="Defer","Status register (owner, risk, follow-on, target date)",IF(AB12="Reject","Record the rationale; close",""))))
AF13: =IF(A13="","",IF(AB13<>"","Closed",IF(X13<>"","With client",IF(L13<>"","Architect reviewed","Draft")))) | AG13: =IF(A13="","",IF(AB13<>"","None",IF(X13<>"","Client",IF(L13<>"","Zero Trust Architect","Identity Architect")))) | AH13: =IF(AB13="Accept and remediate","Remediation backlog (Jira story)",IF(AB13="Accept risk","Exception register (owner, expiry, compensating control)",IF(AB13="Defer","Status register (owner, risk, follow-on, target date)",IF(AB13="Reject","Record the rationale; close",""))))
AF14: =IF(A14="","",IF(AB14<>"","Closed",IF(X14<>"","With client",IF(L14<>"","Architect reviewed","Draft")))) | AG14: =IF(A14="","",IF(AB14<>"","None",IF(X14<>"","Client",IF(L14<>"","Zero Trust Architect","Identity Architect")))) | AH14: =IF(AB14="Accept and remediate","Remediation backlog (Jira story)",IF(AB14="Accept risk","Exception register (owner, expiry, compensating control)",IF(AB14="Defer","Status register (owner, risk, follow-on, target date)",IF(AB14="Reject","Record the rationale; close",""))))
... AF63: =IF(A63="","",IF(AB63<>"","Closed",IF(X63<>"","With client",IF(L63<>"","Architect reviewed","Draft")))) | AG63: =IF(A63="","",IF(AB63<>"","None",IF(X63<>"","Client",IF(L63<>"","Zero Trust Architect","Identity Architect")))) | AH63: =IF(AB63="Accept and remediate","Remediation backlog (Jira story)",IF(AB63="Accept risk","Exception register (owner, expiry, compensating control)",IF(AB63="Defer","Status register (owner, risk, follow-on, target date)",IF(AB63="Reject","Record the rationale; close",""))))

Sheet Gaps
A1: Gap register (control, capability, evidence, coverage and decision gaps; findings stay on the Review Trail)
A2: ID | B2: Type | C2: Gap | D2: Area | E2: Current state | F2: Target state | G2: Impact | H2: Priority | I2: Related findings | J2: Source | K2: Owner | L2: Status | M2: Next step | N2: Raised

Sheet Definitions
A1: Severity
A2: Critical | B2: Reaches Tier 0 (domain or tenant control), or leaves a leaver or an admin with no second factor. Fix or formally accept within the current sprint.
A3: High | B3: Privileged access held outside the intended model, or a gap that affects many accounts. Plan in the next sprint.
A4: Medium | B4: Hygiene gap with limited reach, or one that another control partly covers. Schedule in the remediation backlog.
A5: Low | B5: Housekeeping: naming, ownership records, clean-up of unused objects. Batch with routine work.
A6: Zero Trust maturity (CISA ZTMM v2.0)
A7: Traditional | B7: Manual, static configuration; siloed enforcement; limited visibility.
A8: Initial | B8: Starting automation of attribute assignment and response; some cross-pillar integration.
A9: Advanced | B9: Automated controls and centralized visibility across pillars; policies based on cross-pillar inputs.
A10: Optimal | B10: Fully automated, just-in-time lifecycles and dynamic policies with continuous monitoring.
A11: Zero Trust principles
A12: Verify explicitly | B12: Authenticate and authorize on every request using all available signals.
A13: Use least privilege | B13: Just-in-time and just-enough access; risk-based adaptive policies.
A14: Assume breach | B14: Minimize blast radius, segment access, verify end to end, monitor.
A15: Client decision
A16: Accept and remediate | B16: The client accepts the finding and the proposed solution; it goes to the remediation backlog.
A17: Accept risk | B17: The client accepts the residual risk without remediation; recorded in the exception register with owner, compensating control and expiry.
A18: Defer | B18: Valid finding, not addressed in this phase; recorded in the status register with owner, risk, disposition, follow-on and target date. Never represented as implemented.
A19: Reject | B19: The client does not accept the finding; the rationale is recorded.
A20: Gap type
A21: Control | B21: The environment falls short of the target; groups the findings that show it.
A22: Capability | B22: A process, tool or function that does not exist or is not used (for example no access review process, licensed feature unused).
A23: Evidence | B23: Not assessed yet because access, an export or an input is missing. Never read as a clean result.
A24: Coverage | B24: Asked for by the scope but not measured by any script; needs another source.
A25: Decision | B25: Work is waiting on a decision (platform direction, ownership, scope).
A26: Source | B26: Severity scale: engagement register instructions. Maturity levels and pillars: CISA Zero Trust Maturity Model v2.0 (April 2023), https://www.cisa.gov/zero-trust-maturity-model

Sheet Lists
A1: Severity | B1: Effort | C1: Gate | D1: Pillar | E1: Principle | F1: Maturity | G1: Alignment | H1: Decision | I1: GapType | J1: GapStatus | K1: Priority
A2: Critical | B2: S | C2: G0 Pre-project | D2: Identity | E2: Verify explicitly | F2: Traditional | G2: Aligned | H2: Accept and remediate | I2: Control | J2: Open | K2: High
A3: High | B3: M | C3: G1 | D3: Devices | E3: Use least privilege | F3: Initial | G3: Aligned with changes | H3: Accept risk | I3: Capability | J3: In progress | K3: Medium
A4: Medium | B4: L | C4: G2 | D4: Networks | E4: Assume breach | F4: Advanced | G4: Not aligned | H4: Defer | I4: Evidence | J4: Closed | K4: Low
A5: Low | B5: XL | C5: G3 | D5: Applications and workloads | F5: Optimal | H5: Reject | I5: Coverage | J5: Accepted
C6: G4 | D6: Data | I6: Decision
C7: G5 | D7: Visibility and analytics
C8: Follow-on | D8: Automation and orchestration
D9: Governance
